<?xml version="1.0" ?>
<!-- =================================================================================== -->
<!-- |    This document was autogenerated by xacro from src/mab_rehab/urdf/mab_three_axis.urdf.xacro | -->
<!-- |    EDITING THIS FILE BY HAND IS NOT RECOMMENDED                                 | -->
<!-- =================================================================================== -->
<robot name="mab_three_axis_rehab_robot">
  <!-- ========================================================================
       Visuals / materials
       ======================================================================== -->
  <material name="carbon">
    <color rgba="0.22 0.25 0.30 1.0"/>
  </material>
  <material name="signal">
    <color rgba="0.85 0.43 0.14 1.0"/>
  </material>
  <material name="silver">
    <color rgba="0.700 0.700 0.700 1.000"/>
  </material>
  <link name="base_link">
    <inertial>
      <origin rpy="0 0 0" xyz="-0.0004893152259659719 -0.2513490561575862 -0.11283715805734928"/>
      <mass value="1.6888096724896144"/>
      <inertia ixx="0.011059" ixy="-5e-06" ixz="-9e-06" iyy="0.008847" iyz="0.001084" izz="0.009341"/>
    </inertial>
    <visual>
      <origin rpy="0 0 0" xyz="0 0 0"/>
      <geometry>
        <mesh filename="file:///home/a/wrist_games_data/pr/P6_RehabilitationRobotics/install/complete_system_urdf_description/share/complete_system_urdf_description/meshes/base_link.stl" scale="0.001 0.001 0.001"/>
      </geometry>
      <material name="silver"/>
    </visual>
    <collision>
      <origin rpy="0 0 0" xyz="0 0 0"/>
      <geometry>
        <mesh filename="file:///home/a/wrist_games_data/pr/P6_RehabilitationRobotics/install/complete_system_urdf_description/share/complete_system_urdf_description/meshes/base_link.stl" scale="0.001 0.001 0.001"/>
      </geometry>
    </collision>
  </link>
  <link name="SP_1">
    <inertial>
      <origin rpy="0 0 0" xyz="-0.000157 0.127198 -0.096757"/>
      <mass value="0.7470"/>
      <inertia ixx="0.009477" ixy="+0.000007" ixz="+0.000004" iyy="0.008693" iyz="+0.003381" izz="0.004240"/>
    </inertial>
    <visual>
      <origin rpy="0 0 0" xyz="-0.0003 0.235996 -0.006391"/>
      <geometry>
        <mesh filename="file:///home/a/wrist_games_data/pr/P6_RehabilitationRobotics/install/complete_system_urdf_description/share/complete_system_urdf_description/meshes/SP_1.stl" scale="0.001 0.001 0.001"/>
      </geometry>
      <material name="silver"/>
    </visual>
    <collision>
      <origin rpy="0 0 0" xyz="-0.0003 0.235996 -0.006391"/>
      <geometry>
        <mesh filename="file:///home/a/wrist_games_data/pr/P6_RehabilitationRobotics/install/complete_system_urdf_description/share/complete_system_urdf_description/meshes/SP_1.stl" scale="0.001 0.001 0.001"/>
      </geometry>
    </collision>
  </link>
  <link name="FE_1">
    <inertial>
      <origin rpy="0 0 0" xyz="+0.015907 -0.014594 +0.066041"/>
      <mass value="0.5000"/>
      <inertia ixx="0.002095" ixy="-0.000326" ixz="-0.000239" iyy="0.003856" iyz="-0.000299" izz="0.002659"/>
    </inertial>
    <visual>
      <origin rpy="0 0 0" xyz="0.000339 0.001 0.190609"/>
      <geometry>
        <mesh filename="file:///home/a/wrist_games_data/pr/P6_RehabilitationRobotics/install/complete_system_urdf_description/share/complete_system_urdf_description/meshes/FE_1.stl" scale="0.001 0.001 0.001"/>
      </geometry>
      <material name="silver"/>
    </visual>
    <collision>
      <origin rpy="0 0 0" xyz="0.000339 0.001 0.190609"/>
      <geometry>
        <mesh filename="file:///home/a/wrist_games_data/pr/P6_RehabilitationRobotics/install/complete_system_urdf_description/share/complete_system_urdf_description/meshes/FE_1.stl" scale="0.001 0.001 0.001"/>
      </geometry>
    </collision>
  </link>
  <link name="RU_1">
    <inertial>
      <origin rpy="0 0 0" xyz="-0.085404 +0.069009 -0.080129"/>
      <mass value="0.5350"/>
      <inertia ixx="0.001653" ixy="+0.000097" ixz="-0.000087" iyy="0.001705" iyz="+0.000042" izz="0.001788"/>
    </inertial>
    <visual>
      <origin rpy="0 0 0" xyz="-0.085661 0.001 -0.006391"/>
      <geometry>
        <mesh filename="file:///home/a/wrist_games_data/pr/P6_RehabilitationRobotics/install/complete_system_urdf_description/share/complete_system_urdf_description/meshes/RU_1.stl" scale="0.001 0.001 0.001"/>
      </geometry>
      <material name="silver"/>
    </visual>
    <collision>
      <origin rpy="0 0 0" xyz="-0.085661 0.001 -0.006391"/>
      <geometry>
        <mesh filename="file:///home/a/wrist_games_data/pr/P6_RehabilitationRobotics/install/complete_system_urdf_description/share/complete_system_urdf_description/meshes/RU_1.stl" scale="0.001 0.001 0.001"/>
      </geometry>
    </collision>
  </link>
  <joint name="joint_1" type="revolute">
    <origin rpy="0 0 0" xyz="0.0003 -0.235996 0.006391"/>
    <parent link="base_link"/>
    <child link="SP_1"/>
    <axis xyz="0.0 -1.0 0.0"/>
    <limit effort="100" lower="-1.22173" upper="1.22173" velocity="100"/>
  </joint>
  <joint name="joint_2" type="revolute">
    <origin rpy="0 0 0" xyz="-0.000639 0.234996 -0.197"/>
    <parent link="SP_1"/>
    <child link="FE_1"/>
    <axis xyz="0.0 0.0 -1.0"/>
    <limit effort="100" lower="-1.047198" upper="1.047198" velocity="100"/>
  </joint>
  <joint name="joint_3" type="revolute">
    <origin rpy="0 0 0" xyz="0.086 0.0 0.197"/>
    <parent link="FE_1"/>
    <child link="RU_1"/>
    <axis xyz="1.0 0.0 0.0"/>
    <limit effort="100" lower="-0.523599" upper="0.523599" velocity="100"/>
  </joint>
  <link name="tool0"/>
  <joint name="tool0_fixed" type="fixed">
    <parent link="RU_1"/>
    <child link="tool0"/>
    <origin rpy="0 0 0" xyz="-0.14 0 0"/>
  </joint>
  <!-- ========================================================================
       ros2_control hardware definition
       ======================================================================== -->
  <ros2_control name="mab_hardware" type="system">
    <hardware>
      <plugin>mab_rehab/MABSystemHardware</plugin>
      <param name="bus">SPI</param>
      <param name="data_rate">1M</param>
      <param name="use_pds">true</param>
      <param name="use_regular_can_frames">false</param>
      <param name="pds_id">100</param>
      <param name="power_stage_socket">2</param>
      <param name="fast_mode">false</param>
      <param name="auto_enable_power_stage">true</param>
      <param name="disable_power_stage_on_deactivate">false</param>
      <param name="startup_in_idle_mode">true</param>
      <param name="allow_no_connected_drives">true</param>
      <param name="save_md_configuration_to_flash">false</param>
      <param name="startup_reference_enabled">true</param>
      <param name="safety_limits_enabled">true</param>
      <param name="md_can_watchdog_ms">1000</param>
      <param name="maintenance_reload_enabled">true</param>
      <param name="maintenance_restore_controller">previous</param>
      <param name="maintenance_service_timeout_ms">3000</param>
    </hardware>
    <joint name="joint_1">
      <param name="can_id">37</param>
      <param name="config_path"></param>
      <param name="gear_ratio">0.02857142857142857</param>
      <param name="startup_reference_position">nan</param>
      <param name="safety_position_min">-999.9</param>
      <param name="safety_position_max">999.9</param>
      <param name="safety_max_velocity">2000</param>
      <param name="safety_max_acceleration">500.0</param>
      <param name="safety_max_deceleration">500.0</param>
      <param name="safety_max_torque">200.0</param>
      <param name="position_pid_kp">42.0</param>
      <param name="position_pid_ki">6.0</param>
      <param name="position_pid_kd">0.0</param>
      <param name="position_pid_windup">1.0</param>
      <param name="velocity_pid_kp">2.0</param>
      <param name="velocity_pid_ki">0.02</param>
      <param name="velocity_pid_kd">0.0</param>
      <param name="velocity_pid_windup">0.25</param>
      <param name="impedance_kp">0.0</param>
      <param name="impedance_kd">0.0</param>
      <param name="motor_friction">0.1</param>
      <param name="motor_stiction">0.1</param>
      <command_interface name="position"/>
      <command_interface name="velocity"/>
      <command_interface name="effort"/>
      <state_interface name="position"/>
      <state_interface name="velocity"/>
      <state_interface name="effort"/>
      <state_interface name="voltage"/>
      <state_interface name="gear_ratio"/>
    </joint>
    <joint name="joint_2">
      <param name="can_id">940</param>
      <param name="config_path"></param>
      <param name="gear_ratio">0.1</param>
      <param name="startup_reference_position">nan</param>
      <param name="safety_position_min">-999.9</param>
      <param name="safety_position_max">999.9</param>
      <param name="safety_max_velocity">2000</param>
      <param name="safety_max_acceleration">500.0</param>
      <param name="safety_max_deceleration">500.0</param>
      <param name="safety_max_torque">200.0</param>
      <param name="position_pid_kp">28.0</param>
      <param name="position_pid_ki">4.0</param>
      <param name="position_pid_kd">0.0</param>
      <param name="position_pid_windup">1.0</param>
      <param name="velocity_pid_kp">4.8</param>
      <param name="velocity_pid_ki">0.004</param>
      <param name="velocity_pid_kd">0.0</param>
      <param name="velocity_pid_windup">0.25</param>
      <param name="impedance_kp">0.0</param>
      <param name="impedance_kd">0.0</param>
      <param name="motor_friction">0.1</param>
      <param name="motor_stiction">0.1</param>
      <command_interface name="position"/>
      <command_interface name="velocity"/>
      <command_interface name="effort"/>
      <state_interface name="position"/>
      <state_interface name="velocity"/>
      <state_interface name="effort"/>
      <state_interface name="voltage"/>
      <state_interface name="gear_ratio"/>
    </joint>
    <joint name="joint_3">
      <param name="can_id">941</param>
      <param name="config_path"></param>
      <param name="gear_ratio">0.1</param>
      <param name="startup_reference_position">nan</param>
      <param name="safety_position_min">-999.9</param>
      <param name="safety_position_max">999.9</param>
      <param name="safety_max_velocity">2000</param>
      <param name="safety_max_acceleration">500.0</param>
      <param name="safety_max_deceleration">500.0</param>
      <param name="safety_max_torque">200.0</param>
      <param name="position_pid_kp">21.0</param>
      <param name="position_pid_ki">3.36</param>
      <param name="position_pid_kd">0.0</param>
      <param name="position_pid_windup">1.0</param>
      <param name="velocity_pid_kp">3.6</param>
      <param name="velocity_pid_ki">0.003</param>
      <param name="velocity_pid_kd">0.0</param>
      <param name="velocity_pid_windup">0.25</param>
      <param name="impedance_kp">0.0</param>
      <param name="impedance_kd">0.0</param>
      <param name="motor_friction">0.1</param>
      <param name="motor_stiction">0.1</param>
      <command_interface name="position"/>
      <command_interface name="velocity"/>
      <command_interface name="effort"/>
      <state_interface name="position"/>
      <state_interface name="velocity"/>
      <state_interface name="effort"/>
      <state_interface name="voltage"/>
      <state_interface name="gear_ratio"/>
    </joint>
  </ros2_control>
</robot>
